<?xml version='1.0'?>
<sdf version='1.4'>
  <model name="my_ROS_mobile_robot">
  	<!--If static=true, will be ignored by the physics engine so I can place the components
     properly-->
  	<static>false</static>

  	<link name='chassis'>
  		<pose>0 0 .05 0 0 0</pose>

  		<collision name='collision'>
  			<geometry>
  				<box>
  					<size>.4 .2 .1</size>
  				</box>
  			</geometry>
  		</collision>

  		<visual name='visual'>
  			<geometry>
  				<box>
  					<size>.4 .2 .1</size>
  				</box>
  			</geometry>
  		</visual>

      <!-- From: 
      http://www.theconstructsim.com/how-to-build-a-differential-drive-simulation/ -->
      <collision name='caster_collision'>
        <pose>-0.15 0 -0.05 0 0 0</pose>
        
        <geometry>
          <sphere>
            <radius>0.05</radius>
          </sphere>
        </geometry>

        <surface>
          <friction>
            <ode>
              <mu>0</mu>
              <mu2>0</mu2>
              <slip1>1.0</slip1>
              <slip2>1.0</slip2>
            </ode>
          </friction>
        </surface>

      </collision>

      <visual name='caster_visual'>
        <pose>-0.15 0 -0.05 0 0 0</pose>
        <geometry>
          <sphere>
            <radius>.05</radius>
          </sphere>
        </geometry>
      </visual>

  	</link>

    <link name="left_wheel">
      <pose>0.1 -0.13 0.1 0 1.5707 1.5707</pose>
      
      <collision name="collision">
        <geometry>
          <cylinder>
            <radius>.1</radius>
            <length>.05</length>
          </cylinder>
        </geometry>
      </collision>
      <visual name="visual">
        <geometry>
          <cylinder>
            <radius>.1</radius>
            <length>.05</length>
          </cylinder>
        </geometry>
      </visual>

    </link>

    <link name="right_wheel">
      <pose>0.1 0.13 0.1 0 1.5707 1.5707</pose>
      
      <collision name="collision">
        <geometry>
          <cylinder>
            <radius>.1</radius>
            <length>.05</length>
          </cylinder>
        </geometry>
      </collision>
      <visual name="visual">
        <geometry>
          <cylinder>
            <radius>.1</radius>
            <length>.05</length>
          </cylinder>
        </geometry>
      </visual>

    </link>

    <joint type="revolute" name="left_wheel_hinge">
      <pose>0 0 -0.03 0 0 0</pose>
      <child>left_wheel</child>
      <parent>chassis</parent>
      <axis>
        <xyz>0 1 0</xyz>
      </axis>
    </joint>

    <joint type="revolute" name="right_wheel_hinge">
      <pose>0 0 0.03 0 0 0</pose>
      <child>right_wheel</child>
      <parent>chassis</parent>
      <axis>
        <xyz>0 1 0</xyz>
      </axis>
    </joint>

    <!--
      Allows the movement and control of from ROS programs (using PLUGINS)
    -->
    <plugin name="differential_drive_controller" filename="libgazebo_ros_diff_drive.so">
      <alwaysOn>true</alwaysOn>
      <updateRate>20</updateRate>
      <leftJoint>left_wheel_hinge</leftJoint>
      <rightJoint>right_wheel_hinge</rightJoint>
      <wheelSeparation>0.4</wheelSeparation>
      <wheelDiameter>0.1</wheelDiameter>
      <torque>20</torque>
      <commandTopic>cmd_vel</commandTopic>
      <odometryTopic>odom</odometryTopic>
      <odometryFrame>odom</odometryFrame>
      <robotBaseFrame>base_footprint</robotBaseFrame>

      <legacyMode>false</legacyMode>
      <rosDebugLevel>na</rosDebugLevel>
      <publishWheelTF>false</publishWheelTF>
      <publishWheelJointState>false</publishWheelJointState>
      <wheelAcceleration>0</wheelAcceleration>
      <wheelTorque>5</wheelTorque>
      <odometrySource>1</odometrySource>
      <publishTf>1</publishTf>
    </plugin>

  </model>
</sdf>