<?xml version="1.0" ?>
<!-- =================================================================================== -->
<!-- |    This document was autogenerated by xacro from my_robot.xacro                 | -->
<!-- |    EDITING THIS FILE BY HAND IS NOT RECOMMENDED                                 | -->
<!-- =================================================================================== -->
<!--
	http://www.generationrobots.com/blog/en/2015/02/robotic-simulation-scenarios-with-gazebo-and-ros/#create your own robot model
	
	#######################################################

    To run:
    $ roslaunch my_robot_gazebo my_robot_world.launch paused:=true

    $ rosrun turtlebot_teleop turtlebot_teleop_key /turtlebot_teleop/cmd_vel:=/my_robot/cmd_vel

-->
<robot name="my_robot" xmlns:xacro="http://www.ros.org/wiki/xacro">
  <!--xacro:property name="cameraSize" value="0.05"/>
	<xacro:property name="cameraMass" value="0.1"/-->
  <material name="black">
    <color rgba="0.0 0.0 0.0 1.0"/>
  </material>
  <material name="blue">
    <color rgba="0.0 0.0 0.8 1.0"/>
  </material>
  <material name="green">
    <color rgba="0.0 0.8 0.0 1.0"/>
  </material>
  <material name="grey">
    <color rgba="0.2 0.2 0.2 1.0"/>
  </material>
  <material name="light_grey">
    <color rgba="0.6 0.6 0.6 1"/>
  </material>
  <material name="dark_grey">
    <color rgba="0.3 0.3 0.3 1"/>
  </material>
  <material name="orange">
    <color rgba="1.0 0.423529411765 0.0392156862745 1.0"/>
  </material>
  <material name="brown">
    <color rgba="0.870588235294 0.811764705882 0.764705882353 1.0"/>
  </material>
  <material name="red">
    <color rgba="0.8 0.0 0.0 1.0"/>
  </material>
  <material name="white">
    <color rgba="1.0 1.0 1.0 1.0"/>
  </material>
  <!-- ros_control plugin -->
  <gazebo>
    <plugin filename="libgazebo_ros_control.so" name="gazebo_ros_control">
      <robotNamespace>/my_robot</robotNamespace>
      <robotParam>/robot_description</robotParam>
      <robotSimType>gazebo_ros_control/DefaultRobotHWSim</robotSimType>
    </plugin>
  </gazebo>
  <!--
    The plugin broadcasts a body's pose and rates through ROS nav_msgs::Odometry message.
    The plugin broadcasts pose and rate of a body named "chassis" over ROS topic name "my_robot/odom".
  -->
  <gazebo>
    <plugin filename="libgazebo_ros_p3d.so" name="ground_truth">
      <frameName>map</frameName>
      <bodyName>chassis</bodyName>
      <topicName>my_robot/odom</topicName>
      <updateRate>30.0</updateRate>
    </plugin>
  </gazebo>
  <!-- Chassis -->
  <gazebo reference="chassis">
    <mu1>0.3</mu1>
    <mu2>0.3</mu2>
    <material>Gazebo/Red</material>
  </gazebo>
  <!-- Caster wheel -->
  <gazebo reference="caster_wheel">
    <mu1>0.0</mu1>
    <mu2>0.0</mu2>
    <kp>1000000.0</kp>
    <kd>100.0</kd>
    <minDepth>0.001</minDepth>
    <maxVel>1.0</maxVel>
    <material>Gazebo/Chrome</material>
  </gazebo>
  <gazebo>
    <plugin filename="libgazebo_ros_diff_drive.so" name="differential_drive_controller">
      <robotNamespace>/</robotNamespace>
      <alwaysOn>true</alwaysOn>
      <updateRate>100</updateRate>
      <leftJoint>left_wheel_hinge</leftJoint>
      <rightJoint>right_wheel_hinge</rightJoint>
      <wheelSeparation>0.025</wheelSeparation>
      <wheelDiameter>0.064</wheelDiameter>
      <torque>20</torque>
      <commandTopic>my_robot/cmd_vel</commandTopic>
      <odometryTopic>my_robot/odom</odometryTopic>
      <odometryFrame>odom</odometryFrame>
      <robotBaseFrame>base_footprint</robotBaseFrame>
      <legacyMode>false</legacyMode>
      <rosDebugLevel>Debug</rosDebugLevel>
      <publishWheelTF>true</publishWheelTF>
      <publishWheelJointState>true</publishWheelJointState>
      <wheelAcceleration>5</wheelAcceleration>
      <wheelTorque>20</wheelTorque>
      <publishTf>1</publishTf>
      <odometrySource>encoder</odometrySource>
    </plugin>
  </gazebo>
  <!-- Used for fixing robot to Gazebo 'chassis' -->
  <link name="base_footprint"/>
  <joint name="base_joint" type="fixed">
    <parent link="base_footprint"/>
    <child link="chassis"/>
  </joint>
  <link name="chassis">
    <collision>
      <origin rpy="0 0 0" xyz="0 0 0.032"/>
      <geometry>
        <!--box size="${chassisLength} 
						   ${chassisWidth} 
						   ${chassisHeight}"/-->
        <mesh filename="package://my_robot_description/meshes/chassis.dae"/>
      </geometry>
    </collision>
    <visual>
      <origin rpy="0 0 0" xyz="0 0 0.032"/>
      <geometry>
        <mesh filename="package://my_robot_description/meshes/chassis.dae"/>
      </geometry>
      <material name="red"/>
    </visual>
    <inertial>
      <origin rpy="0 0 0" xyz="0 0 0.032"/>
      <mass value="0.15"/>
      <inertia ixx="0.000225528625" ixy="0" ixz="0" iyy="0.000538566125" iyz="0" izz="0.000538566125"/>
    </inertial>
  </link>
  <joint name="caster_joint" type="fixed">
    <parent link="chassis"/>
    <child link="caster_wheel"/>
  </joint>
  <link name="caster_wheel">
    <collision>
      <origin rpy="0 0 0" xyz="0.091 0 0.042"/>
      <geometry>
        <!--sphere radius="${casterRadius}"/-->
        <mesh filename="package://my_robot_description/meshes/caster_wheel.dae"/>
      </geometry>
    </collision>
    <visual>
      <origin rpy="0 0 0" xyz="0.091 0 0.042"/>
      <geometry>
        <!--sphere radius="${casterRadius}"/-->
        <mesh filename="package://my_robot_description/meshes/caster_wheel.dae"/>
      </geometry>
      <material name="grey"/>
    </visual>
    <inertial>
      <origin rpy="0 0 0" xyz="0.091 0 0.042"/>
      <mass value="0.09"/>
      <inertia ixx="1.5876e-05" ixy="0" ixz="0" iyy="1.5876e-05" iyz="0" izz="1.5876e-05"/>
    </inertial>
  </link>
  <link name="left_wheel">
    <collision>
      <origin rpy="1.57079632679 0 0" xyz="0 0 0"/>
      <geometry>
        <cylinder length="0.026" radius="0.032"/>
        <!--mesh filename="package://my_robot_description/meshes/${lr}_wheel.dae" /-->
      </geometry>
    </collision>
    <visual>
      <origin rpy="1.57079632679 0 0" xyz="0 0 0"/>
      <geometry>
        <!--cylinder 
            length="${wheelWidth}" 
            radius="${wheelRadius}"/-->
        <mesh filename="package://my_robot_description/meshes/left_wheel.dae"/>
      </geometry>
    </visual>
    <inertial>
      <origin rpy="1.57079632679 0 0" xyz="0 0 0"/>
      <mass value="0.05"/>
      <inertia ixx="1.56166666667e-05" ixy="0" ixz="0" iyy="1.56166666667e-05" iyz="0" izz="2.56e-05"/>
    </inertial>
  </link>
  <gazebo reference="left_wheel">
    <mu1 value="1.0"/>
    <mu2 value="1.0"/>
    <kp value="10000000.0"/>
    <kd>100.0</kd>
    <minDepth>0.001</minDepth>
    <maxVel>1.0</maxVel>
    <!--kd  value="1.0" />
      <fdir1 value="1 0 0"/-->
    <material>Gazebo/FlatBlack</material>
  </gazebo>
  <joint name="left_wheel_hinge" type="continuous">
    <parent link="chassis"/>
    <child link="left_wheel"/>
    <origin rpy="0 0 0" xyz="0 0.063 0.032"/>
    <axis rpy="0 0 0" xyz="0 1 0"/>
    <!--limit effort="100" velocity="10"/-->
    <limit effort="0.0" velocity="0.0"/>
    <joint_properties damping="0.0" friction="0.0"/>
  </joint>
  <!--
  http://gazebosim.org/tutorials/?tut=ros_control
-->
  <transmission name="left_trans">
    <type>transmission_interface/SimpleTransmission</type>
    <joint name="left_wheel_hinge">
      <hardwareInterface>hardware_interface/EffortJointInterface</hardwareInterface>
    </joint>
    <actuator name="leftMotor">
      <hardwareInterface>hardware_interface/EffortJointInterface</hardwareInterface>
      <mechanicalReduction>10</mechanicalReduction>
      <!--mechanicalReduction>1</mechanicalReduction-->
    </actuator>
  </transmission>
  <link name="right_wheel">
    <collision>
      <origin rpy="-1.57079632679 0 0" xyz="0 0 0"/>
      <geometry>
        <cylinder length="0.026" radius="0.032"/>
        <!--mesh filename="package://my_robot_description/meshes/${lr}_wheel.dae" /-->
      </geometry>
    </collision>
    <visual>
      <origin rpy="-1.57079632679 0 0" xyz="0 0 0"/>
      <geometry>
        <!--cylinder 
            length="${wheelWidth}" 
            radius="${wheelRadius}"/-->
        <mesh filename="package://my_robot_description/meshes/right_wheel.dae"/>
      </geometry>
    </visual>
    <inertial>
      <origin rpy="-1.57079632679 0 0" xyz="0 0 0"/>
      <mass value="0.05"/>
      <inertia ixx="1.56166666667e-05" ixy="0" ixz="0" iyy="1.56166666667e-05" iyz="0" izz="2.56e-05"/>
    </inertial>
  </link>
  <gazebo reference="right_wheel">
    <mu1 value="1.0"/>
    <mu2 value="1.0"/>
    <kp value="10000000.0"/>
    <kd>100.0</kd>
    <minDepth>0.001</minDepth>
    <maxVel>1.0</maxVel>
    <!--kd  value="1.0" />
      <fdir1 value="1 0 0"/-->
    <material>Gazebo/FlatBlack</material>
  </gazebo>
  <joint name="right_wheel_hinge" type="continuous">
    <parent link="chassis"/>
    <child link="right_wheel"/>
    <origin rpy="0 0 0" xyz="0 -0.063 0.032"/>
    <axis rpy="0 0 0" xyz="0 1 0"/>
    <!--limit effort="100" velocity="10"/-->
    <limit effort="0.0" velocity="0.0"/>
    <joint_properties damping="0.0" friction="0.0"/>
  </joint>
  <!--
  http://gazebosim.org/tutorials/?tut=ros_control
-->
  <transmission name="right_trans">
    <type>transmission_interface/SimpleTransmission</type>
    <joint name="right_wheel_hinge">
      <hardwareInterface>hardware_interface/EffortJointInterface</hardwareInterface>
    </joint>
    <actuator name="rightMotor">
      <hardwareInterface>hardware_interface/EffortJointInterface</hardwareInterface>
      <mechanicalReduction>10</mechanicalReduction>
      <!--mechanicalReduction>1</mechanicalReduction-->
    </actuator>
  </transmission>
  <!--joint name="camera_joint" type="fixed">
		<origin xyz="${-cameraSize+chassisLength/2} 0 ${cameraSize+wheelRadius+cameraSize/2}" rpy="0 0 0"/>
		<parent link="chassis"/>
		<child link="camera"/>
	</joint>

	<link name="camera">
		<collision>
			<origin xyz="0 0 0" rpy="0 0 0"/>
			<geometry>
				<box size="${cameraSize} 
						   ${cameraSize} 
						   ${cameraSize}"/>
			</geometry>
		</collision>

		<visual>
			<origin xyz="0 0 0" rpy="0 0 0"/>
			<geometry>
				<box size="${cameraSize} 
						   ${cameraSize} 
						   ${cameraSize}"/>
			</geometry>
			<material name="blue"/>
		</visual>

		<inertial>
			<mass value="${cameraMass}" />
			<origin xyz="0 0 0" rpy="0 0 0"/>
			<box_inertia m="${cameraMass}" 
						 x="${cameraSize}" 
						 y="${cameraSize}" 
						 z="${cameraSize}" />
		</inertial>
	</link-->
</robot>

